I'm sorry, but an uncaught exception occurred.

While running game code:
  File "game/script.rpy", line 14, in script
    hinata "Whoa, check out that building over there! That’s where they work on advanced AI models! I heard students even train their own AI assistants!"
  File "game/callbacks.rpy", line 11, in char_callback
    current_emotion = filtered_attributes[0]
IndexError: list index out of range

-- Full Traceback ------------------------------------------------------------

Full traceback:
  File "game/script.rpy", line 14, in script
    hinata "Whoa, check out that building over there! That’s where they work on advanced AI models! I heard students even train their own AI assistants!"
  File "c:\Users\user\Downloads\renpy-8.3.6-sdk\renpy\ast.py", line 2586, in execute
    Say.execute(self)
  File "c:\Users\user\Downloads\renpy-8.3.6-sdk\renpy\ast.py", line 623, in execute
    renpy.exports.say(who, what, *args, **kwargs)
  File "c:\Users\user\Downloads\renpy-8.3.6-sdk\renpy\exports\sayexports.py", line 132, in say
    who(what, *args, **kwargs)
  File "c:\Users\user\Downloads\renpy-8.3.6-sdk\renpy\character.py", line 1470, in __call__
    self.do_display(who, what, cb_args=self.cb_args, dtt=dtt, **display_args)
  File "c:\Users\user\Downloads\renpy-8.3.6-sdk\renpy\character.py", line 1117, in do_display
    display_say(who,
  File "c:\Users\user\Downloads\renpy-8.3.6-sdk\renpy\character.py", line 627, in display_say
    callback("begin")
  File "c:\Users\user\Downloads\renpy-8.3.6-sdk\renpy\character.py", line 91, in __call__
    c(*args, **kwargs)
  File "game/callbacks.rpy", line 11, in char_callback
    current_emotion = filtered_attributes[0]
  File "c:\Users\user\Downloads\renpy-8.3.6-sdk\renpy\revertable.py", line 214, in __getitem__
    rv = list.__getitem__(self, index)
IndexError: list index out of range

Windows-10-10.0.26100 AMD64
Ren'Py 8.3.6.25022803
IBM Vision 1.0
Thu Mar 20 00:15:50 2025
